<?xml version="1.0"?>
<robot name="spot_gripper" xmlns:xacro="http://www.ros.org/wiki/xacro">
  <xacro:macro name="load_gripper" params="
		tf_prefix
		include_transmissions:=false">

      <link name="${tf_prefix}arm_link_wr1">
        <visual>
          <origin xyz="0 0 0" rpy="0 0 0" />
          <geometry>
            <mesh filename="package://spot_description/meshes/arm/visual/arm_link_wr1.obj" />
          </geometry>
          <material name="arm_link_wr1">
            <color rgba="0.2 0.2 0.2 1" />
          </material>
        </visual>
        <collision>
          <geometry>
            <mesh filename="package://spot_description/meshes/arm/collision/arm_link_wr1.obj" />
          </geometry>
        </collision>
        <collision>
          <geometry>
            <mesh filename="package://spot_description/meshes/arm/collision/front_jaw.obj" />
          </geometry>
        </collision>
        <collision>
          <geometry>
            <mesh filename="package://spot_description/meshes/arm/collision/middle_jaw.obj" />
          </geometry>
        </collision>
        <collision>
          <geometry>
            <mesh filename="package://spot_description/meshes/arm/collision/jaw_tooth.obj" />
          </geometry>
        </collision>
        <inertial>
          <origin rpy="0.006393076449033863 0.2928526604761865 -0.022814984050994802"
            xyz="0.12516802549362183 0.00010137435310753062 -0.013997982256114483" />
          <mass value="0.785" />
          <inertia ixx="0.00076741362048185" ixy="0.0" ixz="0.0" iyy="0.0017628124054271809" iyz="0.0"
            izz="0.0016818105865345951" />
        </inertial>
      </link>

		<link name="${tf_prefix}arm_link_fngr">
			<visual>
				<origin xyz="0 0 0" rpy="0 0 0"/>
				<geometry>
					<mesh filename="package://spot_description/meshes/arm/visual/arm_link_fngr.obj"/>
				</geometry>
			</visual>
			<collision>
				<geometry>
					<mesh filename="package://spot_description/meshes/arm/collision/left_hinge.obj" />
				</geometry>
			</collision>
			<collision>
				<geometry>
					<mesh filename="package://spot_description/meshes/arm/collision/left_finger.obj" />
				</geometry>
			</collision>
			<collision>
				<geometry>
					<mesh filename="package://spot_description/meshes/arm/collision/left_tooth.obj" />
				</geometry>
			</collision>
			<collision>
				<geometry>
					<mesh filename="package://spot_description/meshes/arm/collision/right_hinge.obj" />
				</geometry>
			</collision>
			<collision>
				<geometry>
					<mesh filename="package://spot_description/meshes/arm/collision/right_finger.obj" />
				</geometry>
			</collision>
			<collision>
				<geometry>
					<mesh filename="package://spot_description/meshes/arm/collision/right_tooth.obj" />
				</geometry>
			</collision>
			<inertial>
				<origin xyz="0.03565178 0.00067200 -0.01227516"/>
				<inertia ixx="0.00025226" ixy="-0.00000536" ixz="-0.00015067" iyy="0.00048453" iyz="0.00000184" izz="0.00059145"/>
				<mass value="0.22383315"/>
			</inertial>
		</link>

		<joint name="${tf_prefix}arm_f1x" type="revolute">
			<origin xyz="0.11745 0.0 0.014820" rpy="0 0 0"/>
			<axis xyz="0.0 1.0 0.0"/>
			<parent link="arm_link_wr1"/>
			<child link="arm_link_fngr"/>
			<!-- The velocity limits are for kinematic planning. The motors might move faster. -->
			<limit effort="15.32" lower="-1.5708" upper="0.0" velocity="10"/>
		</joint>

		<xacro:if value="${include_transmissions}">
			<transmission name="${tf_prefix}arm_f1x_tran">
				<type>transmission_interface/SimpleTransmission</type>
				<joint name="${tf_prefix}arm_f1x">
					<hardwareInterface>EffortJointInterface</hardwareInterface>
				</joint>
				<actuator name="${tf_prefix}arm_f1x_motor">
					<hardwareInterface>EffortJointInterface</hardwareInterface>
				</actuator>
			</transmission>
		</xacro:if>

		<link name="${tf_prefix}arm_link_jaw">
			<collision>
				<geometry>
					<mesh filename="package://spot_description/meshes/arm/collision/front_jaw.obj" />
				</geometry>
			</collision>
			<collision>
				<geometry>
					<mesh filename="package://spot_description/meshes/arm/collision/middle_jaw.obj" />
				 </geometry>
			</collision>
			<collision>
				<geometry>
					<mesh filename="package://spot_description/meshes/arm/collision/jaw_tooth.obj" />
				 </geometry>
			</collision>
		</link>
		<joint name="${tf_prefix}arm_jaw" type="fixed">
			<parent link="arm_link_wr1"/>
			<child link="arm_link_jaw"/>
		</joint>
  </xacro:macro>
</robot>
